Workbook
Name Ts: 'STEP 3 Backup'!$H$12
Name Ts: 'NO FINS STEP 3'!$H$11
Name Ts: 'STEP 3'!$H$12

Sheet Preliminary Calc
A5: Typical Load of Groceries
A6: Medium capacity (3.1 cu ft) can hold approximately 80, 12 oz cans | C6: Source
A8: Calculating the heat that must be removed from a full load
A9: Quantity of cans | B9: 20
A10: Volume per can (oz) | B10: 12 | D10: Can to KJ total conversion
A11: Volume (oz) | B11: =B9*B10 -> 240 | D11: =B10*B12*B14*B16*(B17-B18) -> 27.097938
A12: Conversion (m^3/oz) | B12: =0.000029574 -> 2.9574e-05
A13: Volume (m^3) | B13: =B12*B11 -> 0.00709776
A14: Density of water at 20C (kg/m^3) | B14: 998.2
A15: Mass of water (kg) | B15: =B14*B13 -> 7.084984
A16: Cp of water (kJ/kgC) | B16: 4.18
A17: Room temperature (C) | B17: 21
A18: Refrigeration temperature (C) | B18: 2.7
A19: Q removed (KJ) per entire load | B19: =B15*B16*(B17-B18) -> 541.95877 | C19: Q = mcp(T1-T2)
A21: Calculating the heat transfer through the walls of the refrigerator
A22: Height (in) | B22: 33.4
A23: Depth (in) | B23: 17.5
A24: Width (in) | B24: 18.7
A25: Conversion (m/in) | B25: 0.0254
A26: Height (m) | B26: =B25*B22 -> 0.84836
A27: Depth (m) | B27: =B23*B25 -> 0.4445 | E27: Freezer Qdot calcs
A28: Width (m) | B28: =B24*B25 -> 0.47498 | E28: Freezer temperature | F28: 0
A29: Sides area (m^2) | B29: =B26*B27 -> 0.37709602 | E29: Freezer height (m) | F29: 0.3048
A30: Top area (m^2) | B30: =B27*B28 -> 0.21112861 | E30: Side | F30: =F29*B27 -> 0.1354836
A31: Front/back area (m^2) | B31: =B26*B28 -> 0.40295403 | E31: Front/Back | F31: =F29*B28 -> 0.1447739
A32: Total Surface area (m^2) | B32: =B29*2+B30+B31*2 -> 1.7712287 | E32: Total area | F32: =B30+2*F30+2*F31 -> 0.77164362
A34: Insulation thickness - L (m) | B34: 0.05
A35: Estimated k value (W/mC) | B35: 0.36
A36: Interior h value (W/m^2C) | B36: 10
A37: Exterior h value (W/m^2C) | B37: 10
A38: Rconv, interior air | B38: =1/(B36*B32) -> 0.056457983 | C38: R conv = 1/hA | E38: Rconv, interior air | F38: =1/(B36*F32) -> 0.1295935 | G38: R conv = 1/hA
A39: Rcond, interior coating | E39: Rcond, interior coating
A40: Rcond, insulation | B40: =B34/(B35*B32) -> 0.078413865 | C40: R cond = L/kA | E40: Rcond, insulation | F40: =B34/(B35*F32) -> 0.17999098 | G40: R cond = L/kA
A41: Rcond, exterior shell | E41: Rcond, exterior shell
A42: Rconv, exterior air | B42: =1/(B37*B32) -> 0.056457983 | C42: R conv = 1/hA | E42: Rconv, exterior air | F42: =1/(B37*F32) -> 0.1295935 | G42: R conv = 1/hA
A43: Rtotal | B43: =B38+B40+B42 -> 0.19132983 | E43: Rtotal | F43: =F38+F40+F42 -> 0.43917798
A44: Q_dot (W) | B44: =(B17-B18)/B43 -> 95.646351 | C44: Q = (T1-T2)/Rtotal | E44: Q_dot (kW), freezer walls | F44: =(B17-F28)/F43/1000 -> 0.047816605 | G44: `
A45: Q_dot (kW) | B45: =B44/1000 -> 0.095646351 | C45: kW = W/1000
A47: Calculating the volume of ice require to deal with load + heat transfer
A48: Duration of passive period (hours) | B48: 3
...

Sheet STEP 1
B2: STEP 1: Determine Required Ice volume per different grocery load scenarios
B3: Inputs/Assumptions
B5: Passive Start | C5: 0.70833333
B6: Passive End | C6: 0.83333333
D9: Assuming Rate schedule with 5-8 pm
A10: Need to figure out | D10: Time of Day | E10: Freezer Activated | F10: Heat transfer through refrigerator walls | G10: Heat transfer through freezer walls | H10: Grocery Load (cans) | I10: Grocery Load (kJ) | J10: Total KJ load | K10: Instantaneous kW
A11: how to calculate the time required to freeze the ice | D11: 0 | E11: 0 | F11: =$A$18 -> 0.095646351 | G11: =$A$16*E11 -> 0 | I11: =H11*$A$14 -> 0 | J11: =I11+(G11+F11)/15/60*3600 -> 0.3825854 | K11: =F11+G11+I11/0.25/3600 -> 0.095646351
D12: 0.010416667 | E12: 0 | F12: =$A$18 -> 0.095646351 | G12: =$A$16*E12 -> 0 | I12: =H12*$A$14 -> 0 | J12: =I12+(G12+F12)/15/60*3600 -> 0.3825854 | K12: =F12+G12+I12/0.25/3600 -> 0.095646351
A13: Can to kJ conversion | D13: 0.020833333 | E13: 0 | F13: =$A$18 -> 0.095646351 | G13: =$A$16*E13 -> 0 | I13: =H13*$A$14 -> 0 | J13: =I13+(G13+F13)/15/60*3600 -> 0.3825854 | K13: =F13+G13+I13/0.25/3600 -> 0.095646351
A14: ='Preliminary Calc'!D11 -> 27.097938 | D14: 0.03125 | E14: 0 | F14: =$A$18 -> 0.095646351 | G14: =$A$16*E14 -> 0 | I14: =H14*$A$14 -> 0 | J14: =I14+(G14+F14)/15/60*3600 -> 0.3825854 | K14: =F14+G14+I14/0.25/3600 -> 0.095646351
A15: Heat transfer through freezer walls value | D15: 0.041666667 | E15: 0 | F15: =$A$18 -> 0.095646351 | G15: =$A$16*E15 -> 0 | I15: =H15*$A$14 -> 0 | J15: =I15+(G15+F15)/15/60*3600 -> 0.3825854 | K15: =F15+G15+I15/0.25/3600 -> 0.095646351
A16: ='Preliminary Calc'!F44 -> 0.047816605 | D16: 0.052083333 | E16: 0 | F16: =$A$18 -> 0.095646351 | G16: =$A$16*E16 -> 0 | I16: =H16*$A$14 -> 0 | J16: =I16+(G16+F16)/15/60*3600 -> 0.3825854 | K16: =F16+G16+I16/0.25/3600 -> 0.095646351
A17: Heat transfer through refrigerator walls value | D17: 0.0625 | E17: 0 | F17: =$A$18 -> 0.095646351 | G17: =$A$16*E17 -> 0 | I17: =H17*$A$14 -> 0 | J17: =I17+(G17+F17)/15/60*3600 -> 0.3825854 | K17: =F17+G17+I17/0.25/3600 -> 0.095646351
A18: ='Preliminary Calc'!B45 -> 0.095646351 | D18: 0.072916667 | E18: 0 | F18: =$A$18 -> 0.095646351 | G18: =$A$16*E18 -> 0 | I18: =H18*$A$14 -> 0 | J18: =I18+(G18+F18)/15/60*3600 -> 0.3825854 | K18: =F18+G18+I18/0.25/3600 -> 0.095646351
D19: 0.083333333 | E19: 0 | F19: =$A$18 -> 0.095646351 | G19: =$A$16*E19 -> 0 | I19: =H19*$A$14 -> 0 | J19: =I19+(G19+F19)/15/60*3600 -> 0.3825854 | K19: =F19+G19+I19/0.25/3600 -> 0.095646351
A20: Total required kJ during passive period | D20: 0.09375 | E20: 0 | F20: =$A$18 -> 0.095646351 | G20: =$A$16*E20 -> 0 | I20: =H20*$A$14 -> 0 | J20: =I20+(G20+F20)/15/60*3600 -> 0.3825854 | K20: =F20+G20+I20/0.25/3600 -> 0.095646351
A21: =sum(J79:J91) -> 820.39823 | D21: 0.10416667 | E21: 0 | F21: =$A$18 -> 0.095646351 | G21: =$A$16*E21 -> 0 | I21: =H21*$A$14 -> 0 | J21: =I21+(G21+F21)/15/60*3600 -> 0.3825854 | K21: =F21+G21+I21/0.25/3600 -> 0.095646351
D22: 0.11458333 | E22: 0 | F22: =$A$18 -> 0.095646351 | G22: =$A$16*E22 -> 0 | I22: =H22*$A$14 -> 0 | J22: =I22+(G22+F22)/15/60*3600 -> 0.3825854 | K22: =F22+G22+I22/0.25/3600 -> 0.095646351
A23: KJ to volume of ice conversion (in^3/kJ) | D23: 0.125 | E23: 0 | F23: =$A$18 -> 0.095646351 | G23: =$A$16*E23 -> 0 | I23: =H23*$A$14 -> 0 | J23: =I23+(G23+F23)/15/60*3600 -> 0.3825854 | K23: =F23+G23+I23/0.25/3600 -> 0.095646351
A24: ='Preliminary Calc'!E56 -> 0.19924299 | D24: 0.13541667 | E24: 0 | F24: =$A$18 -> 0.095646351 | G24: =$A$16*E24 -> 0 | I24: =H24*$A$14 -> 0 | J24: =I24+(G24+F24)/15/60*3600 -> 0.3825854 | K24: =F24+G24+I24/0.25/3600 -> 0.095646351
D25: 0.14583333 | E25: 0 | F25: =$A$18 -> 0.095646351 | G25: =$A$16*E25 -> 0 | I25: =H25*$A$14 -> 0 | J25: =I25+(G25+F25)/15/60*3600 -> 0.3825854 | K25: =F25+G25+I25/0.25/3600 -> 0.095646351
A26: Total volume of ice required during passive period | D26: 0.15625 | E26: 0 | F26: =$A$18 -> 0.095646351 | G26: =$A$16*E26 -> 0 | I26: =H26*$A$14 -> 0 | J26: =I26+(G26+F26)/15/60*3600 -> 0.3825854 | K26: =F26+G26+I26/0.25/3600 -> 0.095646351
A27: =A24*A21 -> 163.45859 | D27: 0.16666667 | E27: 0 | F27: =$A$18 -> 0.095646351 | G27: =$A$16*E27 -> 0 | I27: =H27*$A$14 -> 0 | J27: =I27+(G27+F27)/15/60*3600 -> 0.3825854 | K27: =F27+G27+I27/0.25/3600 -> 0.095646351
D28: 0.17708333 | E28: 0 | F28: =$A$18 -> 0.095646351 | G28: =$A$16*E28 -> 0 | I28: =H28*$A$14 -> 0 | J28: =I28+(G28+F28)/15/60*3600 -> 0.3825854 | K28: =F28+G28+I28/0.25/3600 -> 0.095646351
A29: Rectangle area | D29: 0.1875 | E29: 0 | F29: =$A$18 -> 0.095646351 | G29: =$A$16*E29 -> 0 | I29: =H29*$A$14 -> 0 | J29: =I29+(G29+F29)/15/60*3600 -> 0.3825854 | K29: =F29+G29+I29/0.25/3600 -> 0.095646351
A30: =14*14 -> 196 | D30: 0.19791667 | E30: 0 | F30: =$A$18 -> 0.095646351 | G30: =$A$16*E30 -> 0 | I30: =H30*$A$14 -> 0 | J30: =I30+(G30+F30)/15/60*3600 -> 0.3825854 | K30: =F30+G30+I30/0.25/3600 -> 0.095646351
A31: Rectangle height | D31: 0.20833333 | E31: 0 | F31: =$A$18 -> 0.095646351 | G31: =$A$16*E31 -> 0 | I31: =H31*$A$14 -> 0 | J31: =I31+(G31+F31)/15/60*3600 -> 0.3825854 | K31: =F31+G31+I31/0.25/3600 -> 0.095646351
A32: 1 | D32: 0.21875 | E32: 0 | F32: =$A$18 -> 0.095646351 | G32: =$A$16*E32 -> 0 | I32: =H32*$A$14 -> 0 | J32: =I32+(G32+F32)/15/60*3600 -> 0.3825854 | K32: =F32+G32+I32/0.25/3600 -> 0.095646351
A33: Block volume | D33: 0.22916667 | E33: 0 | F33: =$A$18 -> 0.095646351 | G33: =$A$16*E33 -> 0 | I33: =H33*$A$14 -> 0 | J33: =I33+(G33+F33)/15/60*3600 -> 0.3825854 | K33: =F33+G33+I33/0.25/3600 -> 0.095646351
A34: =A30*A32 -> 196 | D34: 0.23958333 | E34: 0 | F34: =$A$18 -> 0.095646351 | G34: =$A$16*E34 -> 0 | I34: =H34*$A$14 -> 0 | J34: =I34+(G34+F34)/15/60*3600 -> 0.3825854 | K34: =F34+G34+I34/0.25/3600 -> 0.095646351
D35: 0.25 | E35: 0 | F35: =$A$18 -> 0.095646351 | G35: =$A$16*E35 -> 0 | I35: =H35*$A$14 -> 0 | J35: =I35+(G35+F35)/15/60*3600 -> 0.3825854 | K35: =F35+G35+I35/0.25/3600 -> 0.095646351
A36: How many blocks | D36: 0.26041667 | E36: 0 | F36: =$A$18 -> 0.095646351 | G36: =$A$16*E36 -> 0 | I36: =H36*$A$14 -> 0 | J36: =I36+(G36+F36)/15/60*3600 -> 0.3825854 | K36: =F36+G36+I36/0.25/3600 -> 0.095646351
A37: =A27/A34 -> 0.83397242 | D37: 0.27083333 | E37: 0 | F37: =$A$18 -> 0.095646351 | G37: =$A$16*E37 -> 0 | I37: =H37*$A$14 -> 0 | J37: =I37+(G37+F37)/15/60*3600 -> 0.3825854 | K37: =F37+G37+I37/0.25/3600 -> 0.095646351
D38: 0.28125 | E38: 0 | F38: =$A$18 -> 0.095646351 | G38: =$A$16*E38 -> 0 | I38: =H38*$A$14 -> 0 | J38: =I38+(G38+F38)/15/60*3600 -> 0.3825854 | K38: =F38+G38+I38/0.25/3600 -> 0.095646351
D39: 0.29166667 | E39: 0 | F39: =$A$18 -> 0.095646351 | G39: =$A$16*E39 -> 0 | I39: =H39*$A$14 -> 0 | J39: =I39+(G39+F39)/15/60*3600 -> 0.3825854 | K39: =F39+G39+I39/0.25/3600 -> 0.095646351
D40: 0.30208333 | E40: 0 | F40: =$A$18 -> 0.095646351 | G40: =$A$16*E40 -> 0 | I40: =H40*$A$14 -> 0 | J40: =I40+(G40+F40)/15/60*3600 -> 0.3825854 | K40: =F40+G40+I40/0.25/3600 -> 0.095646351
D41: 0.3125 | E41: 0 | F41: =$A$18 -> 0.095646351 | G41: =$A$16*E41 -> 0 | I41: =H41*$A$14 -> 0 | J41: =I41+(G41+F41)/15/60*3600 -> 0.3825854 | K41: =F41+G41+I41/0.25/3600 -> 0.095646351
D42: 0.32291667 | E42: 0 | F42: =$A$18 -> 0.095646351 | G42: =$A$16*E42 -> 0 | I42: =H42*$A$14 -> 0 | J42: =I42+(G42+F42)/15/60*3600 -> 0.3825854 | K42: =F42+G42+I42/0.25/3600 -> 0.095646351
D43: 0.33333333 | E43: 0 | F43: =$A$18 -> 0.095646351 | G43: =$A$16*E43 -> 0 | H43: 1 | I43: =H43*$A$14 -> 27.097938 | J43: =I43+(G43+F43)/15/60*3600 -> 27.480524 | K43: =F43+G43+I43/0.25/3600 -> 0.12575517
D44: 0.34375 | E44: 0 | F44: =$A$18 -> 0.095646351 | G44: =$A$16*E44 -> 0 | I44: =H44*$A$14 -> 0 | J44: =I44+(G44+F44)/15/60*3600 -> 0.3825854 | K44: =F44+G44+I44/0.25/3600 -> 0.095646351
...

Sheet STEP 2
A2: ☺ | B2: STEP 2: Determine how long and how much electricity it will take for the ice to freeze
B4: Considerations for when ice is already at 0 degrees | E4: Calculations for bringing ice from 3 to 0 degrees
B6: Energy required for ice to switch phase | C6: Q = mL | F6: Q = mcp(T1-T2)
B7: Latent heat of fusion of ice(kJ/kg) (L) | C7: 334 | E7: Specific heat of water | F7: 4.184 | G7: kJ/kgC
B8: Volume of Ice (From Step 1) in^3 | C8: ='STEP 1'!A27 -> 163.45859 | E8: Initial Temperature (C) | F8: 0
B9: m per inch | C9: 0.0254 | E9: Final Temperature (C) | F9: 0
B10: Volume of Ice m^3 | C10: =C8*C9^3 -> 0.0026786065 | E10: Energy to cool water (kJ) | F10: =C12*F7*(F8-F9) -> 0
B11: Density of Ice (kg/m^3) | C11: ='Preliminary Calc'!B52 -> 917
B12: Mass of Ice (kg) | C12: =C10*C11 -> 2.4562821
B13: Energy taken away to to freeze Ice (KJ) | C13: =C12*C7 -> 820.39823
B16: Total Energy (cool water + freeze) (kJ) | C16: =C13+F10 -> 820.39823 | D16: kJ = kWs
B17: Total Energy (cool water + freeze) (kWh) | C17: =C16/3600 -> 0.2278884 | D17: kWh = kWs*hr/3600 s
B19: Time spent freezing ice (hours) | C19: 3
B20: Time spent freezing ice (seconds) | C20: =C19*3600 -> 10800
B21: Power required to freeze ice over period | C21: =C16/C20 -> 0.075962799
B23: Rate schedule (Non Peak)
B24: Summer ($/kWh) | C24: ='Preliminary Calc'!B61 -> 0.43
B25: Winter ($/kWh) | C25: ='Preliminary Calc'!B64 -> 0.44
B26: Average (#/kWh) | C26: =AVERAGE(C24:C25) -> 0.435
B28: Money cost to freeze ice over period | C28: =C17*C26 -> 0.099131452

Sheet STEP 3
B2: STEP 3: Determine Fan CFM and resulting output temperature based on surface area
B3: Control Panel
B5: Air conditions | F5: Fin and block information | J5: Other
B6: Assumptions for Air conditions | F6: Assumptions for fin and block
B7: a) | C7: R value of air kJ/kg | D7: 0.287 | F7: a) | G7: Fin spacing | H7: 0.1 | J7: a) | K7: Required heat removed (KJ) | L7: ='STEP 1'!A21 -> 820.39823
B8: b) | C8: Atmospheric pressure | D8: 101.325 | F8: b) | G8: Fin thickness (in) | H8: 0.04 | J8: b) | K8: Required heat removed/s (kW) | L8: =L7/3/3600*-1 -> -0.075962799
B9: c) | C9: Refrigeration temperature (K) | D9: =4+273 -> 277 | F9: c) | G9: Length of block (in) | H9: 14 | J9: c) | K9: Ideal refrigeration temperature (C) | L9: 2.77778 | M9: Not used in any calcs atm
B10: d) | C10: Freezer Temperature | D10: 273 | F10: d) | G10: Depth of block (in) | H10: 14 | J10: d) | K10: Conversion (m^3/s per cfm) | L10: 0.00047194745
B11: e) | C11: Average temperature | D11: =average(D9:D10) -> 275 | F11: e) | G11: Fin height | H11: 1 | J11: e) | K11: m per inch | L11: 0.0254
B12: f) | C12: Kinematic Viscosity (v) | D12: =1.46*10^-5 -> 1.46e-05 | E12: Find in tables | F12: g) | G12: Surface temperature of fins | H12: 0 | J12: f)
B13: g) | C13: cp air | D13: =1.005*1000 -> 1005 | E13: J/kg·K | F13: h) | G13: Quantity of ice layers | H13: 2 | J13: g)
B14: h) | C14: Prandtl | D14: 0.71 | E14: Find in tables | F14: i) | G14: Quantity of fin layers | H14: =H13+1 -> 3
B15: i) | C15: Entering air temperature (C) | D15: 4 | F15: Calculated Steps for fin and block
B16: f) | C16: Thermal conductivity of air | D16: =24.59*10^-3 -> 0.02459 | F16: j) | G16: Number of fins | H16: =H9/(H7+H8)*H14 -> 300
B17: Calculated Steps for Air conditions | F17: k)
C18: Average density of air (kg/m^3) | D18: =D8/(D7*D11) -> 1.2838137 | F18: l) | G18: a/b Fin height/spacing | H18: =H11/H7 -> 10
C19: Air dynamic Viscosity (mu) | D19: =D12*D18 -> 1.8743681e-05 | F19: m) | G19: Fin cross sectional area Ac (in)] | H19: =H7*H11 -> 0.1
F20: n) | G20: Fin perimeter P (in) | H20: =(2*H11+H7) -> 2.1
F21: o) | G21: Dh (in) | H21: =4*H19/H20 -> 0.19047619
F22: p) | G22: Dh (m) | H22: =H21*L11 -> 0.0048380952
F23: q) | G23: Nusselt for Laminar table | H23: 2.61
F24: r) | G24: Fin surface area (in) | H24: =H20*H9 -> 29.4
F25: s) | G25: Surface area (m) | H25: =H24*L11^2 -> 0.018967704
G27: =H19*H16 -> 30
B30: volumetric flow (CFM) | C30: 1 | D30: 5 | E30: 10 | F30: 20 | G30: 23 | H30: 26 | I30: 29 | J30: 30 | K30: 33 | L30: 36 | M30: 40 | N30: 50 | O30: 100 | P30: 1000 | Q30: 2000
B31: Volumetric Flow (m^3/s) | C31: =C30*$L$10 -> 0.00047194745 | D31: =D30*$L$10 -> 0.0023597373 | E31: =E30*$L$10 -> 0.0047194745 | F31: =F30*$L$10 -> 0.009438949 | G31: =G30*$L$10 -> 0.010854791 | H31: =H30*$L$10 -> 0.012270634 | I31: =I30*$L$10 -> 0.013686476 | J31: =J30*$L$10 -> 0.014158423 | ... Q31: =Q30*$L$10 -> 0.9438949
B32: Mass flow (kg/s) | C32: =C31*$D$18 -> 0.00060589262 | D32: =D31*$D$18 -> 0.0030294631 | E32: =E31*$D$18 -> 0.0060589262 | F32: =F31*$D$18 -> 0.012117852 | G32: =G31*$D$18 -> 0.01393553 | H32: =H31*$D$18 -> 0.015753208 | I32: =I31*$D$18 -> 0.017570886 | J32: =J31*$D$18 -> 0.018176779 | ... Q32: =Q31*$D$18 -> 1.2117852
B33: Mass flow per fin spac (kg/s) | C33: =C32/$H$16 -> 2.0196421e-06 | D33: =D32/$H$16 -> 1.009821e-05 | E33: =E32/$H$16 -> 2.0196421e-05 | F33: =F32/$H$16 -> 4.0392842e-05 | G33: =G32/$H$16 -> 4.6451768e-05 | H33: =H32/$H$16 -> 5.2510694e-05 | I33: =I32/$H$16 -> 5.856962e-05 | J33: =J32/$H$16 -> 6.0589262e-05 | ... Q33: =Q32/$H$16 -> 0.0040392842
B34: Air velocity (m/s) | C34: =C32/($D$18*$H$19*$L$11*$H$16*$H$14) -> 0.0002064512 | D34: =D32/($D$18*$H$19*$L$11*$H$16*$H$14) -> 0.001032256 | E34: =E32/($D$18*$H$19*$L$11*$H$16*$H$14) -> 0.002064512 | F34: =F32/($D$18*$H$19*$L$11*$H$16*$H$14) -> 0.0041290241 | G34: =G32/($D$18*$H$19*$L$11*$H$16*$H$14) -> 0.0047483777 | H34: =H32/($D$18*$H$19*$L$11*$H$16*$H$14) -> 0.0053677313 | I34: =I32/($D$18*$H$19*$L$11*$H$16*$H$14) -> 0.0059870849 | J34: =J32/($D$18*$H$19*$L$11*$H$16*$H$14) -> 0.0061935361 | ... Q34: =Q32/($D$18*$H$19*$L$11*$H$16*$H$14) -> 0.41290241
B35: Reynolds number | C35: =4*C33/($D$19*PI()*$H$22) -> 28.356671 | D35: =4*D33/($D$19*PI()*$H$22) -> 141.78335 | E35: =4*E33/($D$19*PI()*$H$22) -> 283.56671 | F35: =4*F33/($D$19*PI()*$H$22) -> 567.13341 | G35: =4*G33/($D$19*PI()*$H$22) -> 652.20342 | H35: =4*H33/($D$19*PI()*$H$22) -> 737.27344 | I35: =4*I33/($D$19*PI()*$H$22) -> 822.34345 | J35: =4*J33/($D$19*PI()*$H$22) -> 850.70012 | ... Q35: =4*Q33/($D$19*PI()*$H$22) -> 56713.341
B36: Turbulent? | C36: =if(C35>2300,if(C35<10000,"Transitional","Turbulent"),"Laminar") -> Laminar | D36: =if(D35>2300,if(D35<10000,"Transitional","Turbulent"),"Laminar") -> Laminar | E36: =if(E35>2300,if(E35<10000,"Transitional","Turbulent"),"Laminar") -> Laminar | F36: =if(F35>2300,if(F35<10000,"Transitional","Turbulent"),"Laminar") -> Laminar | G36: =if(G35>2300,if(G35<10000,"Transitional","Turbulent"),"Laminar") -> Laminar | H36: =if(H35>2300,if(H35<10000,"Transitional","Turbulent"),"Laminar") -> Laminar | I36: =if(I35>2300,if(I35<10000,"Transitional","Turbulent"),"Laminar") -> Laminar | J36: =if(J35>2300,if(J35<10000,"Transitional","Turbulent"),"Laminar") -> Laminar | ... Q36: =if(Q35>2300,if(Q35<10000,"Transitional","Turbulent"),"Laminar") -> Turbulent
B37: Entry length | C37: =if(C36="Laminar",0.05*C35*$D$14*$H$22,10*$H$22) -> 0.0048703257 | D37: =if(D36="Laminar",0.05*D35*$D$14*$H$22,10*$H$22) -> 0.024351628 | E37: =if(E36="Laminar",0.05*E35*$D$14*$H$22,10*$H$22) -> 0.048703257 | F37: =if(F36="Laminar",0.05*F35*$D$14*$H$22,10*$H$22) -> 0.097406514 | G37: =if(G36="Laminar",0.05*G35*$D$14*$H$22,10*$H$22) -> 0.11201749 | H37: =if(H36="Laminar",0.05*H35*$D$14*$H$22,10*$H$22) -> 0.12662847 | I37: =if(I36="Laminar",0.05*I35*$D$14*$H$22,10*$H$22) -> 0.14123945 | J37: =if(J36="Laminar",0.05*J35*$D$14*$H$22,10*$H$22) -> 0.14610977 | K37: =if(K36="Laminar",0.05*K35*$D$14*$H$22,10*$H$22) -> 0.16072075 | L37: =if(L36="laminar",0.05*$C$35*$D$14*$H$22,10*$H$22) -> 0.0048703257 | M37: =if(M36="laminar",0.05*$C$35*$D$14*$H$22,10*$H$22) -> 0.0048703257 | N37: =if(N36="laminar",0.05*$C$35*$D$14*$H$22,10*$H$22) -> 0.0048703257 | O37: =if(O36="laminar",0.05*$C$35*$D$14*$H$22,10*$H$22) -> 0.048380952 | P37: =if(P36="laminar",0.05*$C$35*$D$14*$H$22,10*$H$22) -> 0.048380952 | Q37: =10*$H$22 -> 0.048380952
B38: Nusselt Number | C38: =if(C36="Laminar",$H$23, 0.023*C35^0.8*$D$14^0.3) -> 2.61 | D38: =if(D36="Laminar",$H$23, 0.023*D35^0.8*$D$14^0.3) -> 2.61 | E38: =if(E36="Laminar",$H$23, 0.023*E35^0.8*$D$14^0.3) -> 2.61 | F38: =if(F36="Laminar",$H$23, 0.023*F35^0.8*$D$14^0.3) -> 2.61 | G38: =if(G36="Laminar",$H$23, 0.023*G35^0.8*$D$14^0.3) -> 2.61 | H38: =if(H36="Laminar",$H$23, 0.023*H35^0.8*$D$14^0.3) -> 2.61 | I38: =if(I36="Laminar",$H$23, 0.023*I35^0.8*$D$14^0.3) -> 2.61 | J38: =if(J36="Laminar",$H$23, 0.023*J35^0.8*$D$14^0.3) -> 2.61 | ... Q38: =if(Q36="Laminar",$H$23, 0.023*Q35^0.8*$D$14^0.3) -> 131.84192
B39: heat transfer coefficient (W/m^2C) | C39: =C38*$D$16/$H$22 -> 13.265531 | D39: =D38*$D$16/$H$22 -> 13.265531 | E39: =E38*$D$16/$H$22 -> 13.265531 | F39: =F38*$D$16/$H$22 -> 13.265531 | G39: =G38*$D$16/$H$22 -> 13.265531 | H39: =H38*$D$16/$H$22 -> 13.265531 | I39: =I38*$D$16/$H$22 -> 13.265531 | J39: =J38*$D$16/$H$22 -> 13.265531 | ... Q39: =Q38*$D$16/$H$22 -> 670.09695
B41: Leaving air temp required | C41: =$L$8*1000/(C32*$D$13)+$D$15 -> -120.74962 | D41: =$L$8*1000/(D32*$D$13)+$D$15 -> -20.949924 | E41: =$L$8*1000/(E32*$D$13)+$D$15 -> -8.474962 | F41: =$L$8*1000/(F32*$D$13)+$D$15 -> -2.237481 | G41: =$L$8*1000/(G32*$D$13)+$D$15 -> -1.4238965 | H41: =$L$8*1000/(H32*$D$13)+$D$15 -> -0.79806229 | I41: =$L$8*1000/(I32*$D$13)+$D$15 -> -0.30171102 | J41: =$L$8*1000/(J32*$D$13)+$D$15 -> -0.15832065 | ... Q41: =$L$8*1000/(Q32*$D$13)+$D$15 -> 3.9376252
B42: Leaving air temperature provided | C42: =$H$12-($H$12-$D$15)*exp(-1*C39*$H$25/(C33*$D$13)) -> 0 | D42: =$H$12-($H$12-$D$15)*exp(-1*D39*$H$25/(D33*$D$13)) -> 0 | E42: =$H$12-($H$12-$D$15)*exp(-1*E39*$H$25/(E33*$D$13)) -> 1.6532197e-05 | F42: =$H$12-($H$12-$D$15)*exp(-1*F39*$H$25/(F33*$D$13)) -> 0.0081319608 | G42: =$H$12-($H$12-$D$15)*exp(-1*G39*$H$25/(G33*$D$13)) -> 0.018251899 | H42: =$H$12-($H$12-$D$15)*exp(-1*H39*$H$25/(H33*$D$13)) -> 0.033993417 | I42: =$H$12-($H$12-$D$15)*exp(-1*I39*$H$25/(I33*$D$13)) -> 0.055667481 | J42: =$H$12-($H$12-$D$15)*exp(-1*J39*$H$25/(J33*$D$13)) -> 0.064192386 | ... Q42: =$H$12-($H$12-$D$15)*exp(-1*Q39*$H$25/(Q33*$D$13)) -> 0.17469783

Sheet NO FINS STEP 3
B2: STEP 3: Determine Fan CFM and resulting output temperature based on surface area
B3: Control Panel
B5: Air conditions | F5: Fin and block information | J5: Other
B6: Assumptions for Air conditions | F6: Assumptions for fin and block
B7: a) | C7: R value of air kJ/kg | D7: 0.287 | J7: a) | K7: Required heat removed (KJ) | L7: ='STEP 1'!A21 -> 820.39823
B8: b) | C8: Atmospheric pressure | D8: 101.325 | F8: b) | G8: Height of gap (in) | H8: 1 | J8: b) | K8: Required heat removed/s (kW) | L8: =L7/3/3600*-1 -> -0.075962799
B9: c) | C9: Refrigeration temperature (K) | D9: =4+273 -> 277 | F9: c) | G9: Length of block (in) | H9: 14 | J9: c) | K9: Ideal refrigeration temperature (C) | L9: 2.77778 | M9: Not used in any calcs atm
B10: d) | C10: Freezer Temperature | D10: 273 | F10: d) | G10: Depth of block (in) | H10: 14 | J10: d) | K10: Conversion (m^3/s per cfm) | L10: 0.00047194745
B11: e) | C11: Average temperature | D11: =average(D9:D10) -> 275 | F11: g) | G11: Surface temperature of ice | H11: 0 | J11: e) | K11: m per inch | L11: 0.0254
B12: f) | C12: Kinematic Viscosity (v) | D12: =1.46*10^-5 -> 1.46e-05 | E12: Find in tables | F12: h) | G12: Quantity of ice layers | H12: 1 | J12: f) | M12: =9.8*10^-4 -> 0.00098
B13: g) | C13: cp air | D13: =1.005*1000 -> 1005 | E13: J/kg·K | F13: i) | G13: Quantity of surfaces | H13: 2 | J13: g) | M13: =M12/L10 -> 2.0765024
B14: h) | C14: Prandtl | D14: 0.71 | E14: Find in tables
B15: i) | C15: Entering air temperature (C) | D15: 4 | F15: Calculated Steps for fin and block | K15: How tall is the gap (in) | L15: 1
B16: f) | C16: Thermal conductivity of air | D16: =24.59*10^-3 -> 0.02459 | K16: Ac no fin (in^2) | L16: =L15*H9 -> 14
B17: Calculated Steps for Air conditions | F17: k) | G17: Surface rea of block (in) | H17: =H9*H9 -> 196 | K17: P no fin | L17: =2*L15+L16 -> 16
C18: Average density of air (kg/m^3) | D18: =D8/(D7*D11) -> 1.2838137 | F18: l) | G18: a/b height/spacing | H18: =H8/H9 -> 0.071428571 | K18: Dh no fin (in) | L18: =4*L16/L17 -> 3.5
C19: Air dynamic Viscosity (mu) | D19: =D12*D18 -> 1.8743681e-05 | F19: m) | G19: Gap cross sectional area Ac (in)] | H19: =H8*H9 -> 14
G20: Gap cross sectional area Ac (m)] | H20: =H19*L11^2 -> 0.00903224
F21: n) | G21: Perimeter (in) | H21: =H19+2*H8 -> 16
F22: o) | G22: Dh (in) | H22: =4*H19/H21 -> 3.5
F23: p) | G23: Dh (m) | H23: =H22*L11 -> 0.0889
F24: q) | G24: Nusselt for Laminar table | H24: 4
F25: r) | G25: Total surface area (in) | H25: =H17*H13 -> 392
F26: s) | G26: Surface area (m) | H26: =H25*L11^2 -> 0.25290272
D28: =H23^2*pi()/4*100 -> 0.62071666
B30: volumetric flow (CFM) | C30: 1 | D30: 5 | E30: 10 | F30: 20 | G30: 23 | H30: 26 | I30: 29 | J30: 30 | K30: 33 | L30: 36 | M30: 40 | N30: 50 | O30: 100 | P30: 1000 | Q30: 2000
B31: Volumetric Flow (m^3/s) | C31: =C30*$L$10 -> 0.00047194745 | D31: =D30*$L$10 -> 0.0023597373 | E31: =E30*$L$10 -> 0.0047194745 | F31: =F30*$L$10 -> 0.009438949 | G31: =G30*$L$10 -> 0.010854791 | H31: =H30*$L$10 -> 0.012270634 | I31: =I30*$L$10 -> 0.013686476 | J31: =J30*$L$10 -> 0.014158423 | ... Q31: =Q30*$L$10 -> 0.9438949
B32: Mass flow (kg/s) | C32: =C31*$D$18 -> 0.00060589262 | D32: =D31*$D$18 -> 0.0030294631 | E32: =E31*$D$18 -> 0.0060589262 | F32: =F31*$D$18 -> 0.012117852 | G32: =G31*$D$18 -> 0.01393553 | H32: =H31*$D$18 -> 0.015753208 | I32: =I31*$D$18 -> 0.017570886 | J32: =J31*$D$18 -> 0.018176779 | ... Q32: =Q31*$D$18 -> 1.2117852
B33: Air velocity (m/s) | C33: =C32/($D$18*$H$20) -> 0.052251429 | D33: =D32/($D$18*$H$20) -> 0.26125715 | E33: =E32/($D$18*$H$20) -> 0.52251429 | F33: =F32/($D$18*$H$20) -> 1.0450286 | G33: =G32/($D$18*$H$20) -> 1.2017829 | H33: =H32/($D$18*$H$20) -> 1.3585372 | I33: =I32/($D$18*$H$20) -> 1.5152915 | J33: =J32/($D$18*$H$20) -> 1.5675429 | ... Q33: =Q32/($D$18*$H$20) -> 104.50286
B34: Reynolds number | C34: =4*C32/($D$19*PI()*$H$23) -> 462.96605 | D34: =4*D32/($D$19*PI()*$H$23) -> 2314.8303 | E34: =4*E32/($D$19*PI()*$H$23) -> 4629.6605 | F34: =4*F32/($D$19*PI()*$H$23) -> 9259.321 | G34: =4*G32/($D$19*PI()*$H$23) -> 10648.219 | H34: =4*H32/($D$19*PI()*$H$23) -> 12037.117 | I34: =4*I32/($D$19*PI()*$H$23) -> 13426.015 | J34: =4*J32/($D$19*PI()*$H$23) -> 13888.982 | ... Q34: =4*Q32/($D$19*PI()*$H$23) -> 925932.1
B35: Turbulent? | C35: =if(C34>2300,if(C34<10000,"Transitional","Turbulent"),"Laminar") -> Laminar | D35: =if(D34>2300,if(D34<10000,"Transitional","Turbulent"),"Laminar") -> Transitional | E35: =if(E34>2300,if(E34<10000,"Transitional","Turbulent"),"Laminar") -> Transitional | F35: =if(F34>2300,if(F34<10000,"Transitional","Turbulent"),"Laminar") -> Transitional | G35: =if(G34>2300,if(G34<10000,"Transitional","Turbulent"),"Laminar") -> Turbulent | H35: =if(H34>2300,if(H34<10000,"Transitional","Turbulent"),"Laminar") -> Turbulent | I35: =if(I34>2300,if(I34<10000,"Transitional","Turbulent"),"Laminar") -> Turbulent | J35: =if(J34>2300,if(J34<10000,"Transitional","Turbulent"),"Laminar") -> Turbulent | ... Q35: =if(Q34>2300,if(Q34<10000,"Transitional","Turbulent"),"Laminar") -> Turbulent
B36: Entry length | C36: =if(C35="Laminar",0.05*C34*$D$14*$H$23,10*$H$23) -> 1.4610977 | D36: =if(D35="Laminar",0.05*D34*$D$14*$H$23,10*$H$23) -> 0.889 | E36: =if(E35="Laminar",0.05*E34*$D$14*$H$23,10*$H$23) -> 0.889 | F36: =if(F35="Laminar",0.05*F34*$D$14*$H$23,10*$H$23) -> 0.889 | G36: =if(G35="Laminar",0.05*G34*$D$14*$H$23,10*$H$23) -> 0.889 | H36: =if(H35="Laminar",0.05*H34*$D$14*$H$23,10*$H$23) -> 0.889 | I36: =if(I35="Laminar",0.05*I34*$D$14*$H$23,10*$H$23) -> 0.889 | J36: =if(J35="Laminar",0.05*J34*$D$14*$H$23,10*$H$23) -> 0.889 | K36: =if(K35="Laminar",0.05*K34*$D$14*$H$23,10*$H$23) -> 0.889 | L36: =if(L35="laminar",0.05*$C$34*$D$14*$H$23,10*$H$23) -> 0.889 | M36: =if(M35="laminar",0.05*$C$34*$D$14*$H$23,10*$H$23) -> 0.889 | N36: =if(N35="laminar",0.05*$C$34*$D$14*$H$23,10*$H$23) -> 0.889 | O36: =if(O35="laminar",0.05*$C$34*$D$14*$H$23,10*$H$23) -> 0.889 | P36: =if(P35="laminar",0.05*$C$34*$D$14*$H$23,10*$H$23) -> 0.889 | Q36: =10*$H$23 -> 0.889
B37: Nusselt Number | C37: =if(C35="Laminar",$H$24, 0.023*C34^0.8*$D$14^0.4) -> 4 | D37: =if(D35="Laminar",$H$24, 0.023*D34^0.8*$D$14^0.4) -> 9.8593094 | E37: =if(E35="Laminar",$H$22, 0.023*E34^0.8*$D$14^0.4) -> 17.166055 | F37: =if(F35="Laminar",$H$22, 0.023*F34^0.8*$D$14^0.4) -> 29.887837 | G37: =if(G35="Laminar",$H$22, 0.023*G34^0.8*$D$14^0.4) -> 33.423564 | H37: =if(H35="Laminar",$H$22, 0.023*H34^0.8*$D$14^0.4) -> 36.867965 | I37: =if(I35="Laminar",$H$24, 0.023*I34^0.8*$D$14^0.4) -> 40.2336 | J37: =if(J35="Laminar",$H$24, 0.023*J34^0.8*$D$14^0.4) -> 41.339717 | K37: =if(K35="Laminar",$H$24, 0.023*K34^0.8*$D$14^0.4) -> 44.615077 | L37: =if(L35="Laminar",$H$24, 0.023*L34^0.8*$D$14^0.4) -> 47.831334 | M37: =if(M35="Laminar",$H$24, 0.023*M34^0.8*$D$14^0.4) -> 52.037747 | N37: =if(N35="Laminar",$H$24, 0.023*N34^0.8*$D$14^0.4) -> 62.208037 | O37: =if(O35="Laminar",$H$24, 0.023*O34^0.8*$D$14^0.4) -> 108.31048 | P37: =if(P35="Laminar",$H$24, 0.023*P34^0.8*$D$14^0.4) -> 683.39295 | Q37: =if(Q35="Laminar",$H$24, 0.023*Q34^0.8*$D$14^0.4) -> 1189.8562
B38: heat transfer coefficient (W/m^2C) | C38: =C37*$D$16/$H$23 -> 1.1064117 | D38: =D37*$D$16/$H$23 -> 2.7271138 | E38: =E37*$D$16/$H$23 -> 4.7481809 | F38: =F37*$D$16/$H$23 -> 8.2670632 | G38: =G37*$D$16/$H$23 -> 9.2450556 | H38: =H37*$D$16/$H$23 -> 10.197787 | I38: =I37*$D$16/$H$23 -> 11.128731 | J38: =J37*$D$16/$H$23 -> 11.434687 | ... Q38: =Q37*$D$16/$H$23 -> 329.11771
B40: Leaving air temp required | C40: =$L$8*1000/(C32*$D$13)+$D$15 -> -120.74962 | D40: =$L$8*1000/(D32*$D$13)+$D$15 -> -20.949924 | E40: =$L$8*1000/(E32*$D$13)+$D$15 -> -8.474962 | F40: =$L$8*1000/(F32*$D$13)+$D$15 -> -2.237481 | G40: =$L$8*1000/(G32*$D$13)+$D$15 -> -1.4238965 | H40: =$L$8*1000/(H32*$D$13)+$D$15 -> -0.79806229 | I40: =$L$8*1000/(I32*$D$13)+$D$15 -> -0.30171102 | J40: =$L$8*1000/(J32*$D$13)+$D$15 -> -0.15832065 | ... Q40: =$L$8*1000/(Q32*$D$13)+$D$15 -> 3.9376252
B41: Leaving air temperature provided | C41: =$H$11-($H$11-$D$15)*exp(-1*C38*$H$26/(C32*$D$13)) -> 2.5263359 | D41: =$H$11-($H$11-$D$15)*exp(-1*D38*$H$26/(D32*$D$13)) -> 3.1891828 | E41: =$H$11-($H$11-$D$15)*exp(-1*E38*$H$26/(E32*$D$13)) -> 3.2840876 | F41: =$H$11-($H$11-$D$15)*exp(-1*F38*$H$26/(F32*$D$13)) -> 3.3690035 | G41: =$H$11-($H$11-$D$15)*exp(-1*G38*$H$26/(G32*$D$13)) -> 3.3849846 | H41: =$H$11-($H$11-$D$15)*exp(-1*H38*$H$26/(H32*$D$13)) -> 3.3987004 | I41: =$H$11-($H$11-$D$15)*exp(-1*I38*$H$26/(I32*$D$13)) -> 3.4106821 | J41: =$H$11-($H$11-$D$15)*exp(-1*J38*$H$26/(J32*$D$13)) -> 3.4143574 | ... Q41: =$H$11-($H$11-$D$15)*exp(-1*Q38*$H$26/(Q32*$D$13)) -> 3.7357491

Sheet STEP 4
B2: STEP 4: Ensure that the ice will remain frozen and surface temp will stay at 0 C
B4: Ice thickness (in) | C4: 1
B5: Ice thickness (m) | C5: =C4*'STEP 3'!L11 -> 0.0254
B6: Pieces | C6: 10
B7: Thickness of each piece (m) | C7: =C5/C6 -> 0.00254
C9: Temperature
C10: Time (hours) | D10: 0.5 | E10: 1 | F10: 1.5 | G10: 2 | H10: 2.5 | I10: 3
A11: TOP OF ICE | B11: Height from bottom | C11: Time (seconds) | D11: =D10*3600 -> 1800 | E11: =E10*3600 -> 3600 | F11: =F10*3600 -> 5400 | G11: =G10*3600 -> 7200 | H11: =H10*3600 -> 9000 | I11: =I10*3600 -> 10800
A12: 10 | B12: =$C$7*A12 -> 0.0254
A13: 9 | B13: =$C$7*A13 -> 0.02286
A14: 8 | B14: =$C$7*A14 -> 0.02032
A15: 7 | B15: =$C$7*A15 -> 0.01778
A16: 6 | B16: =$C$7*A16 -> 0.01524
A17: 5 | B17: =$C$7*A17 -> 0.0127
A18: 4 | B18: =$C$7*A18 -> 0.01016
A19: 3 | B19: =$C$7*A19 -> 0.00762
A20: 2 | B20: =$C$7*A20 -> 0.00508
A21: 1 | B21: =$C$7*A21 -> 0.00254
A22: Bottom of ice | B22: 0

Sheet Differnet Approach for STEP 4
B2: STEP 4: Ensure that the ice will remain frozen and surface temp will stay at approximately 0 C
B4: Ice thickness (in) | C4: 1 | E4: Initial Temperature of Ice (C) | F4: -3
B5: Ice thickness (m) | C5: =C4*'STEP 3'!L11 -> 0.0254 | E5: Phase change temperature (C) | F5: 0
B6: Ice Volume (in^3) | C6: ='STEP 1'!A27 -> 163.45859
B7: Ice Volume (m^3) | C7: =C6*'STEP 3'!L11^3 -> 0.0026786065 | E7: specific heat of ice (kJ/kgC) | F7: 2.09
B8: Ice Density (kg/m^3) | C8: ='Preliminary Calc'!B52 -> 917 | E8: Heat of fusion (ice) (kJ/kg) | F8: 334
B9: Ice mass (kg) | C9: =C8*C7 -> 2.4562821 | E9: specific heat of water (kJ/kg) | F9: 4.18
B11: Q = mcp(Ti-Tf) | C11: Change Temperature | E11: 21.1 = (2.28*2.09)(-3-Tf)
B12: Q = mL | C12: Phase Change | E12: =D18/(C9*F7) -> 4.4391281
B13: Melting rate (Qin) (kW) | C13: ='STEP 3'!L8*-1 -> 0.075962799
B15: ASSUMING LUMPED (ALL ABOUT THE SAME TEMPERATURE)
B16: Time (minutes) | C16: Time (seconds) | D16: Heat added (kJ) | E16: Average Temperature | F16: Mass of ice melted | H16: State
A17: 0 | B17: =A17*5 -> 0 | C17: =B17*60 -> 0 | D17: =$C$13*C17 -> 0 | E17: =F4 -> -3 | H17: =if(E17<0,"Frozen,heating",if(E17>0,"Liquid,heating","Melting")) -> Frozen,heating
A18: 1 | B18: =A18*5 -> 5 | C18: =B18*60 -> 300 | D18: =$C$13*C18 -> 22.78884 | E18: =E17+D18/(C9*F7) -> 1.4391281 | H18: =if(E18<0,"Frozen,heating",if(E18>0,"Liquid,heating","Melting")) -> Liquid,heating
A19: 2 | B19: =A19*5 -> 10 | C19: =B19*60 -> 600 | D19: =$C$13*C19 -> 45.577679 | H19: =if(E19<0,"Frozen,heating",if(E19>0,"Liquid,heating","Melting")) -> Melting
A20: 3 | B20: =A20*5 -> 15 | C20: =B20*60 -> 900 | D20: =$C$13*C20 -> 68.366519 | H20: =if(E20<0,"Frozen,heating",if(E20>0,"Liquid,heating","Melting")) -> Melting
A21: 4 | B21: =A21*5 -> 20 | C21: =B21*60 -> 1200 | D21: =$C$13*C21 -> 91.155359 | H21: =if(E21<0,"Frozen,heating",if(E21>0,"Liquid,heating","Melting")) -> Melting
A22: 5 | B22: =A22*5 -> 25 | C22: =B22*60 -> 1500 | D22: =$C$13*C22 -> 113.9442 | H22: =if(E22<0,"Frozen,heating",if(E22>0,"Liquid,heating","Melting")) -> Melting
A23: 6 | B23: =A23*5 -> 30 | C23: =B23*60 -> 1800 | D23: =$C$13*C23 -> 136.73304 | H23: =if(E23<0,"Frozen,heating",if(E23>0,"Liquid,heating","Melting")) -> Melting
A24: 7 | B24: =A24*5 -> 35 | C24: =B24*60 -> 2100 | D24: =$C$13*C24 -> 159.52188 | H24: =if(E24<0,"Frozen,heating",if(E24>0,"Liquid,heating","Melting")) -> Melting
A25: 8 | B25: =A25*5 -> 40 | C25: =B25*60 -> 2400 | D25: =$C$13*C25 -> 182.31072 | H25: =if(E25<0,"Frozen,heating",if(E25>0,"Liquid,heating","Melting")) -> Melting
A26: 9 | B26: =A26*5 -> 45 | C26: =B26*60 -> 2700 | D26: =$C$13*C26 -> 205.09956 | H26: =if(E26<0,"Frozen,heating",if(E26>0,"Liquid,heating","Melting")) -> Melting
A27: 10 | B27: =A27*5 -> 50 | C27: =B27*60 -> 3000 | D27: =$C$13*C27 -> 227.8884 | H27: =if(E27<0,"Frozen,heating",if(E27>0,"Liquid,heating","Melting")) -> Melting
A28: 11 | B28: =A28*5 -> 55 | C28: =B28*60 -> 3300 | D28: =$C$13*C28 -> 250.67724 | H28: =if(E28<0,"Frozen,heating",if(E28>0,"Liquid,heating","Melting")) -> Melting
A29: 12 | B29: =A29*5 -> 60 | C29: =B29*60 -> 3600 | D29: =$C$13*C29 -> 273.46608 | H29: =if(E29<0,"Frozen,heating",if(E29>0,"Liquid,heating","Melting")) -> Melting
A30: 13 | B30: =A30*5 -> 65 | C30: =B30*60 -> 3900 | D30: =$C$13*C30 -> 296.25492 | H30: =if(E30<0,"Frozen,heating",if(E30>0,"Liquid,heating","Melting")) -> Melting
... A32: 15 | B32: =A32*5 -> 75 | C32: =B32*60 -> 4500 | D32: =$C$13*C32 -> 341.83259 | H32: =if(E32<0,"Frozen,heating",if(E32>0,"Liquid,heating","Melting")) -> Melting

Sheet STEP 3 Backup
B2: STEP 3: Determine Fan CFM and resulting output temperature based on surface area
B3: Control Panel
B5: Air conditions | F5: Fin and block information | J5: Other
B6: Assumptions for Air conditions | F6: Assumptions for fin and block
B7: a) | C7: R value of air kJ/kg | D7: 0.287 | F7: a) | G7: Fin spacing | H7: 0.1 | J7: a) | K7: Required heat removed (KJ) | L7: ='STEP 1'!A21 -> 820.39823
B8: b) | C8: Atmospheric pressure | D8: 101.325 | F8: b) | G8: Fin thickness (in) | H8: 0.04 | J8: b) | K8: Required heat removed/s (kW) | L8: =L7/3/3600*-1 -> -0.075962799
B9: c) | C9: Refrigeration temperature (K) | D9: =4+273 -> 277 | F9: c) | G9: Length of block (in) | H9: 14 | J9: c) | K9: Ideal refrigeration temperature (C) | L9: 2.77778 | M9: Not used in any calcs atm
B10: d) | C10: Freezer Temperature | D10: 273 | F10: d) | G10: Depth of block (in) | H10: 14 | J10: d) | K10: Conversion (m^3/s per cfm) | L10: 0.00047194745
B11: e) | C11: Average temperature | D11: =average(D9:D10) -> 275 | F11: e) | G11: Fin height | H11: 1 | J11: e) | K11: m per inch | L11: 0.0254
B12: f) | C12: Kinematic Viscosity (v) | D12: =1.46*10^-5 -> 1.46e-05 | E12: Find in tables | F12: g) | G12: Surface temperature of fins | H12: 0 | J12: f)
B13: g) | C13: cp air | D13: =1.005*1000 -> 1005 | E13: J/kg·K | F13: h) | G13: Quantity of ice layers | H13: 1 | J13: g)
B14: h) | C14: Prandtl | D14: 0.71 | E14: Find in tables | F14: i) | G14: Quantity of fin layers | H14: 2
B15: i) | C15: Entering air temperature (C) | D15: 4 | F15: Calculated Steps for fin and block | K15: How tall is the gap (in) | L15: 1
B16: f) | C16: Thermal conductivity of air | D16: =24.59*10^-3 -> 0.02459 | F16: j) | G16: Number of fins | H16: =H9/(H7+H8) -> 100 | K16: Ac no fin (in^2) | L16: =L15*H9 -> 14
B17: Calculated Steps for Air conditions | F17: k) | G17: Area of block (in) | H17: =H9*H9 -> 196 | K17: P no fin | L17: =2*L15+L16 -> 16
C18: Average density of air (kg/m^3) | D18: =D8/(D7*D11) -> 1.2838137 | F18: l) | G18: a/b Fin height/spacing | H18: =H11/H7 -> 10 | K18: Dh no fin (in) | L18: =4*L16/L17 -> 3.5
C19: Air dynamic Viscosity (mu) | D19: =D12*D18 -> 1.8743681e-05 | F19: m) | G19: Fin cross sectional area Ac (in)] | H19: =H7*H11 -> 0.1
F20: n) | G20: Fin perimeter P (in) | H20: =(2*H11+H7) -> 2.1
F21: o) | G21: Dh (in) | H21: =4*H19/H20 -> 0.19047619
F22: p) | G22: Dh (m) | H22: =H21*L11 -> 0.0048380952
F23: q) | G23: Nusselt for Laminar table | H23: 6
F24: r) | G24: Fin surface area (in) | H24: =(H11*H9)*H16*H14*2 -> 5600
F25: s) | G25: Surface area (m) | H25: =H24*L11^2 -> 3.612896
G27: =H19*H16 -> 10
D28: =H22^2*pi()/4*100 -> 0.0018383945
B30: volumetric flow (CFM) | C30: 1 | D30: 5 | E30: 10 | F30: 20 | G30: 23 | H30: 26 | I30: 29 | J30: 30 | K30: 33 | L30: 36 | M30: 40 | N30: 50 | O30: 100 | P30: 1000 | Q30: 2000
B31: Volumetric Flow (m^3/s) | C31: =C30*$L$10 -> 0.00047194745 | D31: =D30*$L$10 -> 0.0023597373 | E31: =E30*$L$10 -> 0.0047194745 | F31: =F30*$L$10 -> 0.009438949 | G31: =G30*$L$10 -> 0.010854791 | H31: =H30*$L$10 -> 0.012270634 | I31: =I30*$L$10 -> 0.013686476 | J31: =J30*$L$10 -> 0.014158423 | ... Q31: =Q30*$L$10 -> 0.9438949
B32: Mass flow (kg/s) | C32: =C31*$D$18 -> 0.00060589262 | D32: =D31*$D$18 -> 0.0030294631 | E32: =E31*$D$18 -> 0.0060589262 | F32: =F31*$D$18 -> 0.012117852 | G32: =G31*$D$18 -> 0.01393553 | H32: =H31*$D$18 -> 0.015753208 | I32: =I31*$D$18 -> 0.017570886 | J32: =J31*$D$18 -> 0.018176779 | ... Q32: =Q31*$D$18 -> 1.2117852
B33: Air velocity (m/s) | C33: =C32/($D$18*$H$19*$L$11*$H$16*$H$14) -> 0.00092903041 | D33: =D32/($D$18*$H$19*$L$11*$H$16*$H$14) -> 0.0046451521 | E33: =E32/($D$18*$H$19*$L$11*$H$16*$H$14) -> 0.0092903041 | F33: =F32/($D$18*$H$19*$L$11*$H$16*$H$14) -> 0.018580608 | G33: =G32/($D$18*$H$19*$L$11*$H$16*$H$14) -> 0.0213677 | H33: =H32/($D$18*$H$19*$L$11*$H$16*$H$14) -> 0.024154791 | I33: =I32/($D$18*$H$19*$L$11*$H$16*$H$14) -> 0.026941882 | J33: =J32/($D$18*$H$19*$L$11*$H$16*$H$14) -> 0.027870912 | ... Q33: =Q32/($D$18*$H$19*$L$11*$H$16*$H$14) -> 1.8580608
B34: Reynolds number | C34: =4*C32/($D$19*PI()*$H$22) -> 8507.0012 | D34: =4*D32/($D$19*PI()*$H$22) -> 42535.006 | E34: =4*E32/($D$19*PI()*$H$22) -> 85070.012 | F34: =4*F32/($D$19*PI()*$H$22) -> 170140.02 | G34: =4*G32/($D$19*PI()*$H$22) -> 195661.03 | H34: =4*H32/($D$19*PI()*$H$22) -> 221182.03 | I34: =4*I32/($D$19*PI()*$H$22) -> 246703.03 | J34: =4*J32/($D$19*PI()*$H$22) -> 255210.04 | ... Q34: =4*Q32/($D$19*PI()*$H$22) -> 17014002
B35: Turbulent? | C35: =if(C34>2300,if(C34<10000,"Transitional","Turbulent"),"Laminar") -> Transitional | D35: =if(D34>2300,if(D34<10000,"Transitional","Turbulent"),"Laminar") -> Turbulent | E35: =if(E34>2300,if(E34<10000,"Transitional","Turbulent"),"Laminar") -> Turbulent | F35: =if(F34>2300,if(F34<10000,"Transitional","Turbulent"),"Laminar") -> Turbulent | G35: =if(G34>2300,if(G34<10000,"Transitional","Turbulent"),"Laminar") -> Turbulent | H35: =if(H34>2300,if(H34<10000,"Transitional","Turbulent"),"Laminar") -> Turbulent | I35: =if(I34>2300,if(I34<10000,"Transitional","Turbulent"),"Laminar") -> Turbulent | J35: =if(J34>2300,if(J34<10000,"Transitional","Turbulent"),"Laminar") -> Turbulent | ... Q35: =if(Q34>2300,if(Q34<10000,"Transitional","Turbulent"),"Laminar") -> Turbulent
B36: Entry length | C36: =if(C35="Laminar",0.05*C34*$D$14*$H$22,10*$H$22) -> 0.048380952 | D36: =if(D35="Laminar",0.05*D34*$D$14*$H$22,10*$H$22) -> 0.048380952 | E36: =if(E35="Laminar",0.05*E34*$D$14*$H$22,10*$H$22) -> 0.048380952 | F36: =if(F35="Laminar",0.05*F34*$D$14*$H$22,10*$H$22) -> 0.048380952 | G36: =if(G35="Laminar",0.05*G34*$D$14*$H$22,10*$H$22) -> 0.048380952 | H36: =if(H35="Laminar",0.05*H34*$D$14*$H$22,10*$H$22) -> 0.048380952 | I36: =if(I35="Laminar",0.05*I34*$D$14*$H$22,10*$H$22) -> 0.048380952 | J36: =if(J35="Laminar",0.05*J34*$D$14*$H$22,10*$H$22) -> 0.048380952 | K36: =if(K35="Laminar",0.05*K34*$D$14*$H$22,10*$H$22) -> 0.048380952 | L36: =if(L35="laminar",0.05*$C$34*$D$14*$H$22,10*$H$22) -> 0.048380952 | M36: =if(M35="laminar",0.05*$C$34*$D$14*$H$22,10*$H$22) -> 0.048380952 | N36: =if(N35="laminar",0.05*$C$34*$D$14*$H$22,10*$H$22) -> 0.048380952 | O36: =if(O35="laminar",0.05*$C$34*$D$14*$H$22,10*$H$22) -> 0.048380952 | P36: =if(P35="laminar",0.05*$C$34*$D$14*$H$22,10*$H$22) -> 0.048380952 | Q36: =10*$H$22 -> 0.048380952
B37: Nusselt Number | C37: =if(C35="Laminar",$H$23, 0.023*C34^0.8*$D$14^0.4) -> 27.928806 | D37: =if(D35="Laminar",$H$23, 0.023*D34^0.8*$D$14^0.4) -> 101.21115 | E37: =if(E35="Laminar",$H$21, 0.023*E34^0.8*$D$14^0.4) -> 176.21885 | F37: =if(F35="Laminar",$H$21, 0.023*F34^0.8*$D$14^0.4) -> 306.81484 | G37: =if(G35="Laminar",$H$21, 0.023*G34^0.8*$D$14^0.4) -> 343.111 | H37: =if(H35="Laminar",$H$21, 0.023*H34^0.8*$D$14^0.4) -> 378.46964 | I37: =if(I35="Laminar",$H$23, 0.023*I34^0.8*$D$14^0.4) -> 413.0197 | J37: =if(J35="Laminar",$H$23, 0.023*J34^0.8*$D$14^0.4) -> 424.37459 | K37: =if(K35="Laminar",$H$23, 0.023*K34^0.8*$D$14^0.4) -> 457.99794 | L37: =if(L35="Laminar",$H$23, 0.023*L34^0.8*$D$14^0.4) -> 491.01456 | M37: =if(M35="Laminar",$H$23, 0.023*M34^0.8*$D$14^0.4) -> 534.19567 | N37: =if(N35="Laminar",$H$23, 0.023*N34^0.8*$D$14^0.4) -> 638.59921 | O37: =if(O35="Laminar",$H$23, 0.023*O34^0.8*$D$14^0.4) -> 1111.8658 | P37: =if(P35="Laminar",$H$23, 0.023*P34^0.8*$D$14^0.4) -> 7015.3989 | Q37: =if(Q35="Laminar",$H$23, 0.023*Q34^0.8*$D$14^0.4) -> 12214.519
B38: heat transfer coefficient (W/m^2C) | C38: =C37*$D$16/$H$22 -> 141.95036 | D38: =D37*$D$16/$H$22 -> 514.41366 | E38: =E37*$D$16/$H$22 -> 895.6462 | F38: =F37*$D$16/$H$22 -> 1559.4106 | G38: =G37*$D$16/$H$22 -> 1743.8887 | H38: =H37*$D$16/$H$22 -> 1923.6018 | I38: =I37*$D$16/$H$22 -> 2099.2052 | J38: =J37*$D$16/$H$22 -> 2156.9173 | ... Q38: =Q37*$D$16/$H$22 -> 62081.254
B40: Leaving air temp required | C40: =$L$8*1000/(C32*$D$13)+$D$15 -> -120.74962 | D40: =$L$8*1000/(D32*$D$13)+$D$15 -> -20.949924 | E40: =$L$8*1000/(E32*$D$13)+$D$15 -> -8.474962 | F40: =$L$8*1000/(F32*$D$13)+$D$15 -> -2.237481 | G40: =$L$8*1000/(G32*$D$13)+$D$15 -> -1.4238965 | H40: =$L$8*1000/(H32*$D$13)+$D$15 -> -0.79806229 | I40: =$L$8*1000/(I32*$D$13)+$D$15 -> -0.30171102 | J40: =$L$8*1000/(J32*$D$13)+$D$15 -> -0.15832065 | ... Q40: =$L$8*1000/(Q32*$D$13)+$D$15 -> 3.9376252
B41: Leaving air temperature provided | C41: =$H$12-($H$12-$D$15)*exp(-1*$C$38*$H$25/($C$32*$D$13)) -> 0 | D41: =$H$12-($H$12-$D$15)*exp(-1*$C$38*$H$25/($C$32*$D$13)) -> 0 | E41: =$H$12-($H$12-$D$15)*exp(-1*$C$38*$H$25/($C$32*$D$13)) -> 0 | F41: =$H$12-($H$12-$D$15)*exp(-1*$C$38*$H$25/($C$32*$D$13)) -> 0 | G41: =$H$12-($H$12-$D$15)*exp(-1*$C$38*$H$25/($C$32*$D$13)) -> 0 | H41: =$H$12-($H$12-$D$15)*exp(-1*$C$38*$H$25/($C$32*$D$13)) -> 0 | I41: =$H$12-($H$12-$D$15)*exp(-1*$C$38*$H$25/($C$32*$D$13)) -> 0 | J41: =$H$12-($H$12-$D$15)*exp(-1*$C$38*$H$25/($C$32*$D$13)) -> 0 | ... Q41: =$H$12-($H$12-$D$15)*exp(-1*$C$38*$H$25/($C$32*$D$13)) -> 0

Sheet Calculations R1
A3: Proof of concept --> Considering the heat transfer through the refrigerator's walls and a typical load of new groceries, what is the volume of ice required?
A5: Typical Load of Groceries
A6: Medium capacity (3.1 cu ft) can hold approximately 80, 12 oz cans | C6: Source
G7: Calculations based off of this size refrigerator | J7: Source
A8: Calculating the heat that must be removed from a full load
A9: Quantity of cans | B9: 20
A10: Volume per can (oz) | B10: 12
A11: Volume (oz) | B11: =B9*B10 -> 240
A12: Conversion (m^3/oz) | B12: =0.000029574 -> 2.9574e-05
A13: Volume (m^3) | B13: =B12*B11 -> 0.00709776
A14: Density of water at 20C (kg/m^3) | B14: 998.2
A15: Mass of water (kg) | B15: =B14*B13 -> 7.084984
A16: Cp of water (kJ/kgC) | B16: 4.18
A17: Room temperature (C) | B17: 21
A18: Refrigeration temperature (C) | B18: 4
A19: Q Grocery Load (KJ) per entire load | B19: =B15*B16*(B17-B18) -> 503.45897 | C19: Q = mcp(T1-T2)
A21: Calculating the heat transfer through the walls of the refrigerator
A22: Height (in) | B22: 33.4
A23: Depth (in) | B23: 17.5
A24: Width (in) | B24: 18.7
A25: Conversion (m/in) | B25: 0.0254
A26: Height (m) | B26: =B25*B22 -> 0.84836
A27: Depth (m) | B27: =B23*B25 -> 0.4445
A28: Width (m) | B28: =B24*B25 -> 0.47498
A29: Sides area (m^2) | B29: =B26*B27 -> 0.37709602
A30: Top area (m^2) | B30: =B27*B28 -> 0.21112861
A31: Front/back area (m^2) | B31: =B26*B28 -> 0.40295403
A32: Total Surface area (m^2) | B32: =B29*2+B30+B31*2 -> 1.7712287
A34: Insulation thickness - L (m) | B34: 0.05
A35: Estimated k value (W/mC) | B35: 0.36
A36: Interior h value (W/m^2C) | B36: 10
A37: Exterior h value (W/m^2C) | B37: 10
A38: Rconv, interior air | B38: =1/(B36*B32) -> 0.056457983 | C38: R conv = 1/hA
A39: Rcond, interior coating
A40: Rcond, insulation | B40: =B34/(B35*B32) -> 0.078413865 | C40: R cond = L/kA
A41: Rcond, exterior shell
A42: Rconv, exterior air | B42: =1/(B37*B32) -> 0.056457983 | C42: R conv = 1/hA
A43: Rtotal | B43: =B38+B40+B42 -> 0.19132983
A44: Q_dot (W) | B44: =(B17-B18)/B43 -> 88.851801 | C44: Q = (T1-T2)/Rtotal | G44: `
A45: Q_dot (kW) | B45: =B44/1000 -> 0.088851801 | C45: kW = W/1000
...
